<?xml version="1.0" ?>
<robot name="box">
    <link name="world"/>
    <link name="s_0">
        <inertial>
            <origin xyz="0. -0.0 0" rpy="0.0 0.0 0.0"/>

            <!-- <mass value="2.5"/>
            <inertia ixx="0.104285" ixy="0.0" ixz="0.0" iyy="0.006785" iyz="0.0" izz="0.106785"/> -->
            <mass value="2.25"/>
            <inertia ixx="0.093858" ixy="0.0" ixz="0.0" iyy="0.006107" iyz="0.0" izz="0.096107"/>


            <!-- <mass value="2.0"/>
            <inertia ixx="0.083428" ixy="0.0" ixz="0.0" iyy="0.005428" iyz="0.0" izz="0.085428"/>  -->
            <!-- <mass value="1.9"/>
            <inertia ixx="0.079256" ixy="0.0" ixz="0.0" iyy="0.005156" iyz="0.0" izz="0.081156"/> -->
<!--             
            <mass value="1.85"/>
            <inertia ixx="0.077171" ixy="0.0" ixz="0.0" iyy="0.005021" iyz="0.0" izz="0.079021"/> -->

            
            <!-- <mass value="1.8"/>
            <inertia ixx="0.075085" ixy="0.0" ixz="0.0" iyy="0.004885" iyz="0.0" izz="0.076885"/> -->

            <!-- <mass value="1.7"/>
            <inertia ixx="0.070914" ixy="0.0" ixz="0.0" iyy="0.004614" iyz="0.0" izz="0.072614"/> -->
            
            <!-- <mass value="1.6"/>
            <inertia ixx="0.066742" ixy="0.0" ixz="0.0" iyy="0.004342" iyz="0.0" izz="0.068342"/> -->




            <!-- <mass value="1.5"/>
            <inertia ixx="0.062571" ixy="0.0" ixz="0.0" iyy="0.004071" iyz="0.0" izz="0.064071"/> -->
<!-- 
            <mass value="1.0"/>
            <inertia ixx="0.041714" ixy="0.0" ixz="0.0" iyy="0.002714" iyz="0.0" izz="0.042714"/>  -->
            <!-- <mass value="0.7"/>
            <inertia ixx="0.0292" ixy="0.0" ixz="0.0" iyy="0.0019" iyz="0.0" izz="0.0299"/>    -->
             <!-- <mass value="0.8"/>
            <inertia ixx="0.0333712" ixy="0.0" ixz="0.0" iyy="0.0021712" iyz="0.0" izz="0.0341712"/>   -->
        </inertial>  
        <visual>
            <origin xyz="0. -0.0 0" rpy="0.0 0.0 0.0"/>
            <geometry>
                <box size="0.15 0.7 0.1"/>
            </geometry>
        </visual>
        <collision>
            <origin xyz="0.0 -0.0 0.0" rpy="0.0 0.0 0.0"/>
            <geometry>
                <box size="0.15 0.7 0.08"/>
            </geometry>
        </collision>
    </link>
        <!-- <link name="s_1">
        <inertial>
            <origin xyz="0. 0.0 0." rpy="0.0 0.0 0.0"/>
            <mass value="0.07"/>
            <inertia ixx="0.0010651041666666667" ixy="0.0" ixz="0.0" iyy="3.3854166666666665e-05" iyz="0.0" izz="0.0010520833333333333"/>

        </inertial>
        <visual>
            <origin xyz="0. 0.0 0." rpy="0.0 0.0 0.0"/>
            <geometry>
                 <box size="0.05 0.5 0.175"/>
            </geometry>
        </visual>
        <collision>
            <origin xyz="0. 0.0 0." rpy="0.0 0.0 0.0"/>
            <geometry>
                 <box size="0.05 0.5 0.075"/>
            </geometry>
        </collision> 
     </link>  -->
    
    <joint name="joint_world_s_0" type="floating">
        <origin xyz="0.2 -0.0 1.04" rpy="0 0 0"/>
        <parent link="world"/>
        <child link="s_0"/>
    </joint>
        <!-- <joint name="joint_s_0_s_1" type="floating">
        <origin xyz="0. 0 0." rpy="0 0 0"/>
        <parent link="s_0"/>
        <child link="s_1"/>
    </joint> -->
</robot>
